Workbook

Sheet Outputs
B1: знак | C1: Контрольные показатели | D1: Тип показателя | E1: Наименование | F1: Источник/ Формула для расчета | G1: Ед. измерения | H1: 2018 | I1: 2019 | J1: 2020 | K1: 2021 | L1: 2022 | M1: 2023 | N1: 2024 | O1: 2025 | P1: 2026 | Q1: 2027 | R1: 2028 | S1: 2029 | T1: 2030 | U1: 2031 | V1: 2032 | W1: 2033 | X1: 2034 | Y1: 2035 | Z1: 2036 | AA1: 2037 | AB1: 2038 | AC1: 2039 | AD1: 2040
B2: + | C2: Финансовый показатель | D2: Общий (обязательный) | E2: Выручка | F2: Отчет о финансовых результатах | G2: USD млн | H2: ='P&L'!L8 -> 3931.847 | I2: ='P&L'!M8 -> 3283.514 | J2: ='P&L'!N8 -> 2649.963 | K2: ='P&L'!O8 -> 4414.559 | L2: ='P&L'!P8 -> 4311.188 | M2: ='P&L'!Q8 -> 3168.5897 | N2: ='P&L'!R8 -> 4407.8544 | O2: ='P&L'!S8 -> 4887.5047 | ... V2: ='P&L'!Z8 -> 4808.972
B3: + | C3: Расчетный показатель | D3: Общий (обязательный) | E3: Операционные расходы (без амортизации) | F3: Предзаполненная формула | G3: =$G$2 -> USD млн | H3: =H2-H6 -> 2784.9191 | I3: =I2-I6 -> 2747.7192 | J3: =J2-J6 -> 2325.5461 | K3: =K2-K6 -> 3241.7675 | L3: =L2-L6 -> 3369.1625 | M3: =M2-M6 -> 2568.8677 | N3: =N2-N6 -> 3458.3718 | O3: =O2-O6 -> 3803.5377 | ... AD3: =AD2-AD6 -> 0
C4: Расчетный показатель | D4: Общий (обязательный) | E4: Коммерческие и управленческие расходы | F4: Отчет о финансовых результатах | G4: =$G$2 -> USD млн
B5: + | C5: Финансовый показатель | D5: Общий (обязательный) | E5: Прибыль от реализации | F5: Отчет о финансовых результатах | G5: =$G$2 -> USD млн
C6: Расчетный показатель | D6: Общий (обязательный) | E6: EBITDA | F6: см. лист формулы | G6: =$G$2 -> USD млн | H6: ='P&L'!L17 -> 1146.9279 | I6: ='P&L'!M17 -> 535.79477 | J6: ='P&L'!N17 -> 324.41686 | K6: ='P&L'!O17 -> 1172.7915 | L6: ='P&L'!P17 -> 942.02546 | M6: ='P&L'!Q17 -> 599.72192 | N6: ='P&L'!R17 -> 949.48262 | O6: ='P&L'!S17 -> 1083.967 | ... V6: ='P&L'!Z17 -> 1007.8291
C7: Расчетный показатель | D7: Общий (обязательный) | E7: Рентабельность EBITDA | F7: Предзаполненная формула | G7: % | H7: =IFERROR(H6/H2,"") -> 0.29170206 | I7: =IFERROR(I6/I2,"") -> 0.16317725 | J7: =IFERROR(J6/J2,"") -> 0.12242317 | K7: =IFERROR(K6/K2,"") -> 0.26566448 | L7: =IFERROR(L6/L2,"") -> 0.21850716 | M7: =IFERROR(M6/M2,"") -> 0.18927093 | N7: =IFERROR(N6/N2,"") -> 0.21540698 | O7: =IFERROR(O6/O2,"") -> 0.22178332 | ... AD7: =IFERROR(AD6/AD2,"")
B8: + | C8: Финансовый показатель | D8: Общий (обязательный) | E8: Амортизация | F8: Приложение к Бухгалтерскому балансу; информация от клиента (заполняется абсолютное значение со знаком +) | G8: =$G$2 -> USD млн | H8: ='P&L'!L20 -> 245.303 | I8: ='P&L'!M20 -> 344.127 | J8: ='P&L'!N20 -> 357.129 | K8: ='P&L'!O20 -> 363.084 | L8: ='P&L'!P20 -> 372.42 | M8: ='P&L'!Q20 -> 358.28537 | N8: ='P&L'!R20 -> 378.29411 | O8: ='P&L'!S20 -> 361.26797 | ... V8: ='P&L'!Z20 -> 284.61719
C9: Финансовый показатель | D9: Общий (обязательный) | E9: Прочие доходы и расходы после EBIT (включая налог на прибыль) | F9: Предзаполненная формула | G9: =$G$2 -> USD млн | H9: =H6-H10-H8 -> 243.641 | I9: =I6-I10-I8 -> 75.302 | J9: =J6-J10-J8 -> 92.615 | K9: =K6-K10-K8 -> 253.797 | L9: =L6-L10-L8 -> 107.317 | M9: =M6-M10-M8 -> 174.70265 | N9: =N6-N10-N8 -> 230.8744 | O9: =O6-O10-O8 -> 245.29011 | ... AD9: =AD6-AD10-AD8 -> 0
C10: Финансовый показатель | D10: Общий (обязательный) | E10: Чистая прибыль | F10: Отчет о финансовых результатах | G10: =$G$2 -> USD млн | H10: ='P&L'!L39 -> 657.98389 | I10: ='P&L'!M39 -> 116.36577 | J10: ='P&L'!N39 -> -125.32714 | K10: ='P&L'!O39 -> 555.91053 | L10: ='P&L'!P39 -> 462.28846 | M10: ='P&L'!Q39 -> 66.733909 | N10: ='P&L'!R39 -> 340.31411 | O10: ='P&L'!S39 -> 477.40894 | ... V10: ='P&L'!Z39 -> 547.37267
C11: Расчетный показатель | D11: Общий (обязательный) | E11: Рентабельность чистой прибыли | F11: Предзаполненная формула | G11: % | H11: =IFERROR(H10/H2,"") -> 0.16734728 | I11: =IFERROR(I10/I2,"") -> 0.035439402 | J11: =IFERROR(J10/J2,"") -> -0.04729392 | K11: =IFERROR(K10/K2,"") -> 0.12592663 | L11: =IFERROR(L10/L2,"") -> 0.10722995 | M11: =IFERROR(M10/M2,"") -> 0.021061076 | N11: =IFERROR(N10/N2,"") -> 0.077206296 | O11: =IFERROR(O10/O2,"") -> 0.097679486 | ... AD11: =IFERROR(AD10/AD2,"")
B13: + | C13: Финансовый показатель | D13: Общий (обязательный) | E13: Остаток денежных средств на конец периода | G13: =$G$2 -> USD млн | H13: =CFS!L32 -> 256.077 | I13: =CFS!M32 -> 416.763 | J13: =CFS!N32 -> 833.841 | K13: =CFS!O32 -> 932.069 | L13: =CFS!P32 -> 857.747 | M13: =CFS!Q32 -> 589.22299 | N13: =CFS!R32 -> 552.97392 | O13: =CFS!S32 -> 966.62759 | ... V13: =CFS!Z32 -> 2472.0674
C14: Финансовый показатель | D14: Общий (обязательный) | E14: Чистый денежный поток за период (NCF) | F14: Предзаполненная формула | G14: =$G$2 -> USD млн | H14: =H15+H16+H17 -> 264.549 | I14: =I15+I16+I17 -> -60.232 | J14: =J15+J16+J17 -> -125.269 | K14: =K15+K16+K17 -> 388.193 | L14: =L15+L16+L17 -> 113.427 | M14: =M15+M16+M17 -> -268.52401 | N14: =N15+N16+N17 -> -36.249069 | O14: =O15+O16+O17 -> 413.65367 | ... AD14: =AD15+AD16+AD17 -> 0
C15: Финансовый показатель | D15: Общий (обязательный) | E15: Денежные потоки от текущих операций (CFO) | F15: Отчет о движении денежных средств | G15: =$G$2 -> USD млн | H15: =CFS!L12 -> 980.206 | I15: =CFS!M12 -> 515.431 | J15: =CFS!N12 -> 461.082 | K15: =CFS!O12 -> 994.369 | L15: =CFS!P12 -> 987.349 | M15: =CFS!Q12 -> 605.80242 | N15: =CFS!R12 -> 778.40913 | O15: =CFS!S12 -> 939.82855 | ... V15: =CFS!Z12 -> 883.18181
C16: Финансовый показатель | D16: Общий (обязательный) | E16: Денежные потоки от инвестиционных операций (CFI) | F16: Отчет о движении денежных средств | G16: =$G$2 -> USD млн | H16: =CFS!L18 -> -306.351 | I16: =CFS!M18 -> -250.692 | J16: =CFS!N18 -> -278.063 | K16: =CFS!O18 -> -253.048 | L16: =CFS!P18 -> -553.137 | M16: =CFS!Q18 -> -590.34062 | N16: =CFS!R18 -> -180.83022 | O16: =CFS!S18 -> -184.55384 | ... V16: =CFS!Z18 -> -212.11736
C17: Финансовый показатель | D17: Общий (обязательный) | E17: Денежные потоки от финансовых операций (CFF) | F17: Отчет о движении денежных средств | G17: =$G$2 -> USD млн | H17: =CFS!L21+CFS!L22+CFS!L23 -> -409.306 | I17: =CFS!M21+CFS!M22+CFS!M23 -> -324.971 | J17: =CFS!N21+CFS!N22+CFS!N23 -> -308.288 | K17: =CFS!O21+CFS!O22+CFS!O23 -> -353.128 | L17: =CFS!P21+CFS!P22+CFS!P23 -> -320.785 | M17: =CFS!Q21+CFS!Q22+CFS!Q23 -> -283.98581 | N17: =CFS!R21+CFS!R22+CFS!R23 -> -633.82798 | O17: =CFS!S21+CFS!S22+CFS!S23 -> -341.62104 | ... V17: =CFS!Z21+CFS!Z22+CFS!Z23 -> -257.25073
C18: Расчетный показатель | D18: Общий (обязательный) | E18: Свободный денежный поток (FCFF) | F18: Предзаполненная формула (см. лист формулы) | G18: =$G$2 -> USD млн | H18: =H15-H21+H35*(1-INDIRECT("Inputs!AA34")) -> 807.7364 | I18: =I15-I21+I35*(1-INDIRECT("Inputs!AA34")) -> 399.1904 | J18: =J15-J21+J35*(1-INDIRECT("Inputs!AA34")) -> 464.656 | K18: =K15-K21+K35*(1-INDIRECT("Inputs!AA34")) -> 1022.9312 | L18: =L15-L21+L35*(1-INDIRECT("Inputs!AA34")) -> 971.1008 | M18: =M15-M21+M35*(1-INDIRECT("Inputs!AA34")) -> 583.04046 | N18: =N15-N21+N35*(1-INDIRECT("Inputs!AA34")) -> 720.14807 | O18: =O15-O21+O35*(1-INDIRECT("Inputs!AA34")) -> 864.34735 | ... V18: =V15-V21+V35*(1-INDIRECT("Inputs!AA34")) -> 711.8033 | W18: =W15-W21+W35*(1-INDIRECT("Inputs!AT34")) -> 0 | X18: =X15-X21+X35*(1-INDIRECT("Inputs!AT34")) -> 0 | Y18: =Y15-Y21+Y35*(1-INDIRECT("Inputs!AT34")) -> 0 | Z18: =Z15-Z21+Z35*(1-INDIRECT("Inputs!AT34")) -> 0 | AA18: =AA15-AA21+AA35*(1-INDIRECT("Inputs!AT34")) -> 0 | AB18: =AB15-AB21+AB35*(1-INDIRECT("Inputs!AT34")) -> 0 | AC18: =AC15-AC21+AC35*(1-INDIRECT("Inputs!AT34")) -> 0 | AD18: =AD15-AD21+AD35*(1-INDIRECT("Inputs!AT34")) -> 0
C19: Расчетный показатель | D19: Общий (обязательный) | E19: Денежные средства, доступные для обслуживания долга (CFADS) | F19: Предзаполненная формула | G19: =$G$2 -> USD млн | H19: =H15+H35-H23 -> 825.738 | I19: =I15+I35-I23 -> 422.247 | J19: =J15+J35-J23 -> 497.746 | K19: =K15+K35-K23 -> 1055.943 | L19: =L15+L35-L23 -> 1003.464 | M19: =M15+M35-M23 -> 614.93513 | N19: =N15+N35-N23 -> 750.79036 | O19: =O15+O35-O23 -> 891.61551 | ... AD19: =AD15+AD35-AD23 -> 0
B21: + | C21: Финансовый показатель | D21: Общий (обязательный) | E21: Сумма капитальных затрат (CAPEX) | F21: Отчет о движении денежных средств; информация от клиента | G21: =$G$2 -> USD млн | H21: =H22+H23 -> 244.476 | I21: =I22+I23 -> 208.467 | J21: =J22+J23 -> 128.786 | K21: =K22+K23 -> 103.485 | L21: =L22+L23 -> 145.701 | M21: =M22+M23 -> 150.34062 | N21: =N22+N23 -> 180.83022 | O21: =O22+O23 -> 184.55384 | ... AD21: =AD22+AD23 -> 0
B22: + | C22: Финансовый показатель | D22: Общий (заполняется при наличии информации) | E22: Капитальные затраты на развитие (Development CAPEX) | F22: Информация от клиента | G22: =$G$2 -> USD млн
B23: + | C23: Финансовый показатель | D23: Общий (обязательный) | E23: Капитальные затраты на поддержание (Maintenance CAPEX) | F23: Информация от клиента; экспертнообоснованный КП уровень, согласованный с АР | G23: =$G$2 -> USD млн | H23: =-CFS!L15 -> 244.476 | I23: =-CFS!M15 -> 208.467 | J23: =-CFS!N15 -> 128.786 | K23: =-CFS!O15 -> 103.485 | L23: =-CFS!P15 -> 145.701 | M23: =-CFS!Q15 -> 150.34062 | N23: =-CFS!R15 -> 180.83022 | O23: =-CFS!S15 -> 184.55384 | ... V23: =-CFS!Z15 -> 212.11736
B25: + | C25: Финансовый показатель | D25: Общий (обязательный) | E25: Долг (Debt) | F25: см. лист формулы | G25: =$G$2 -> USD млн | H25: =PRINT!L25 -> 1458.286 | I25: =PRINT!M25 -> 2487.358 | J25: =PRINT!N25 -> 3085.606 | K25: =PRINT!O25 -> 2875.293 | L25: =PRINT!P25 -> 3021.676 | M25: =PRINT!Q25 -> 2913.847 | N25: =PRINT!R25 -> 2518.309 | O25: =PRINT!S25 -> 2432.381 | ... V25: =PRINT!Z25 -> 489.579
B26: + | C26: Финансовый показатель | D26: Общий (обязательный) | E26: Долг без учета задолженности по лизингу | F26: Информация по клиенту | G26: =$G$2 -> USD млн
B27: + | C27: Финансовый показатель | D27: Общий (обязательный) | E27: Долг с учетом забалансовых обязательств | F27: см. лист формулы | G27: =$G$2 -> USD млн
C28: Расчетный показатель | D28: Общий (обязательный) | E28: Чистый долг (Net Debt) | F28: см. лист формулы | G28: =$G$2 -> USD млн | H28: =PRINT!L28 -> 1202.209 | I28: =PRINT!M28 -> 2070.595 | J28: =PRINT!N28 -> 2251.765 | K28: =PRINT!O28 -> 1943.224 | L28: =PRINT!P28 -> 2163.929 | M28: =PRINT!Q28 -> 2324.624 | N28: =PRINT!R28 -> 1965.3351 | O28: =PRINT!S28 -> 1465.7534 | ... V28: =PRINT!Z28 -> -1982.4884
C29: Расчетный показатель | D29: Общий (обязательный) | E29: Долгосрочные кредиты и займы | F29: Бухгалтерский баланс | G29: =$G$2 -> USD млн
C30: Расчетный показатель | D30: Общий (обязательный) | E30: Краткосрочные кредиты и займы | F30: Бухгалтерский баланс | G30: =$G$2 -> USD млн
C31: Расчетный показатель | D31: Общий (обязательный) | E31: Обязательства по финансовому лизингу | F31: см. лист формулы | G31: =$G$2 -> USD млн
B32: + | C32: Финансовый показатель | D32: Общий (обязательный) | E32: Балансирующий долг | F32: Информация по клиенту | G32: =$G$2 -> USD млн
B33: + | C33: Расчетный показатель | D33: Общий (обязательный) | E33: Обслуживание долга (Debt Service) | F33: Предзаполненная формула | G33: =$G$2 -> USD млн | H33: =H34+H35+H38 -> 90.008 | I33: =I34+I35+I38 -> 115.283 | J33: =J34+J35+J38 -> 165.45 | K33: =K34+K35+K38 -> 165.059 | L33: =L34+L35+L38 -> 161.816 | M33: =M34+M35+M38 -> 159.47333 | N33: =N34+N35+N38 -> 153.21145 | O33: =O34+O35+O38 -> 136.3408 | ... AD33: =AD34+AD35+AD38 -> 0
B34: + | C34: Расчетный показатель | D34: Общий (обязательный) | E34: Погашение основного долга | F34: Отчет о движении денежных средств; информация, полученная от клиента | G34: =$G$2 -> USD млн
B35: + | C35: Финансовый показатель | D35: Общий (обязательный) | E35: Платежи процентов по долговым обязательствам | F35: Отчет о движении денежных средств; информация, полученная от клиента | G35: =$G$2 -> USD млн | H35: =-CFS!L22 -> 90.008 | I35: =-CFS!M22 -> 115.283 | J35: =-CFS!N22 -> 165.45 | K35: =-CFS!O22 -> 165.059 | L35: =-CFS!P22 -> 161.816 | M35: =-CFS!Q22 -> 159.47333 | N35: =-CFS!R22 -> 153.21145 | O35: =-CFS!S22 -> 136.3408 | ... V35: =-CFS!Z22 -> 50.92356
B36: + | C36: Финансовый показатель | D36: Общий (обязательный) | E36: Начисленные проценты по долговым обязательствам | F36: Информация по клиенту | G36: =$G$2 -> USD млн
B37: + | C37: Финансовый показатель | D37: Общий (обязательный) | E37: Капитализированные проценты | F37: Информация по клиенту | G37: =$G$2 -> USD млн
B38: + | C38: Финансовый показатель | D38: Общий (обязательный) | E38: Лизинговые платежи (вкл. основной долг в их составе) | F38: Предзаполненная формула | G38: =$G$2 -> USD млн | H38: =H39+H40 -> 0 | I38: =I39+I40 -> 0 | J38: =J39+J40 -> 0 | K38: =K39+K40 -> 0 | L38: =L39+L40 -> 0 | M38: =M39+M40 -> 0 | N38: =N39+N40 -> 0 | O38: =O39+O40 -> 0 | ... AD38: =AD39+AD40 -> 0
B39: + | C39: Финансовый показатель | D39: Общий (обязательный) | E39: Лизинговые платежи | F39: Отчет о финансовых результатах; информация, полученная от клиента | G39: =$G$2 -> USD млн
B40: + | C40: Финансовый показатель | D40: Общий (обязательный) | E40: Платежи процентов по лизингу | F40: Отчет о финансовых результатах; информация, полученная от клиента | G40: =$G$2 -> USD млн
C41: Финансовый показатель | D41: Общий (обязательный) | E41: Эффект от переоценки валютного долга | F41: Информация по клиенту | G41: =$G$2 -> USD млн
B42: + | C42: Финансовый показатель | D42: Общий (обязательный) | E42: Привлечение денежных средств (итого) | F42: = Кредиты без подтверждения финансирования + кредиты с подтверждением финансирования + прочие привлечения Отчет о движении денежных средств, информация, полученная от клиента | G42: =$G$2 -> USD млн
C43: Финансовый показатель | D43: Общий (обязательный) | E43: Оборотный капитал на конец периода | F43: = Оборотные (текущие) активы (код 1600) – Оборотные (текущие) пассивы (код 1700), Бухгалтерский баланс | G43: =$G$2 -> USD млн
...

Sheet PRINT
E2: Scenario | F2: 1 | G2: =G13/G7 -> 85.230989 | H2: =H13/H7 -> 94.862472 | I2: =I13/I7 -> 49.527249 | J2: =J13/J7 -> 25.73639 | K2: =K13/K7 -> 73.548422 | L2: =L13/L7 -> 102.33118 | M2: =M13/M7 -> 48.122398 | N2: =N13/N7 -> 30.206412 | ... Z2: =Z13/Z7 -> 86.984989
E4: Показатель | F4: Ед.изм. | G4: =Calc!G2 -> 2013 | H4: =Calc!H2 -> 2014 | I4: =Calc!I2 -> 2015 | J4: =Calc!J2 -> 2016 | K4: =Calc!K2 -> 2017 | L4: =Calc!L2 -> 2018 | M4: =Calc!M2 -> 2019 | N4: =Calc!N2 -> 2020 | ... Z4: =Calc!Z2 -> 2032
E5: Операционные показатели
E6: Объем производства метанола | F6: млн т | G6: =Calc!G42/1000 -> 4.344 | H6: =Calc!H42/1000 -> 4.853 | I6: =Calc!I42/1000 -> 5.193 | J6: =Calc!J42/1000 -> 7.017 | K6: =Calc!K42/1000 -> 7.187 | L6: =Calc!L42/1000 -> 7.211 | M6: =Calc!M42/1000 -> 7.589 | N6: =Calc!N42/1000 -> 6.614 | ... Z6: =Calc!Z42/1000 -> 7.738
E7: Объем продажи метанола | F7: млн т | G7: =Calc!G63/1000 -> 7.991 | H7: =Calc!H63/1000 -> 8.504 | I7: =Calc!I63/1000 -> 8.471 | J7: =Calc!J63/1000 -> 9.478 | K7: =Calc!K63/1000 -> 10.669 | L7: =Calc!L63/1000 -> 11.208 | M7: =Calc!M63/1000 -> 11.134 | N7: =Calc!N63/1000 -> 10.74 | ... Z7: =Calc!Z63/1000 -> 11.586242
E8: Цена реализации метанола | F8: $/т | G8: =Calc!G68 -> 378.43161 | H8: =Calc!H68 -> 379.04504 | I8: =Calc!I68 -> 262.73191 | J8: =Calc!J68 -> 210.84923 | K8: =Calc!K68 -> 286.87243 | L8: =Calc!L68 -> 350.80719 | M8: =Calc!M68 -> 294.90875 | N8: =Calc!N68 -> 246.73771 | ... Z8: =Calc!Z68 -> 415.05883
E9: Изменение | F9: % | G9: =IFERROR(G8/F8-1,"-") -> - | H9: =IFERROR(H8/G8-1,"-") -> 0.0016209721 | I9: =IFERROR(I8/H8-1,"-") -> -0.30685833 | J9: =IFERROR(J8/I8-1,"-") -> -0.19747384 | K9: =IFERROR(K8/J8-1,"-") -> 0.36055718 | L9: =IFERROR(L8/K8-1,"-") -> 0.22286825 | M9: =IFERROR(M8/L8-1,"-") -> -0.15934235 | N9: =IFERROR(N8/M8-1,"-") -> -0.16334218 | ... Z9: =IFERROR(Z8/Y8-1,"-") -> 0.004
E10: Финансовые показатели
E11: Выручка | F11: млн $ | G11: ='P&L'!G8 -> 3024.047 | H11: ='P&L'!H8 -> 3223.399 | I11: ='P&L'!I8 -> 2225.602 | J11: ='P&L'!J8 -> 1998.429 | K11: ='P&L'!K8 -> 3060.642 | L11: ='P&L'!L8 -> 3931.847 | M11: ='P&L'!M8 -> 3283.514 | N11: ='P&L'!N8 -> 2649.963 | ... Z11: ='P&L'!Z8 -> 4808.972
E12: Темп прироста выручки | F12: % | G12: =IFERROR(G11/F11-1,"-") -> - | H12: =IFERROR(H11/G11-1,"-") -> 0.065922256 | I12: =IFERROR(I11/H11-1,"-") -> -0.30954809 | J12: =IFERROR(J11/I11-1,"-") -> -0.10207261 | K12: =IFERROR(K11/J11-1,"-") -> 0.53152401 | L12: =IFERROR(L11/K11-1,"-") -> 0.2846478 | M12: =IFERROR(M11/L11-1,"-") -> -0.16489273 | N12: =IFERROR(N11/M11-1,"-") -> -0.19294908 | ... Z12: =IFERROR(Z11/Y11-1,"-") -> 0.004
E13: EBITDA | F13: млн $ | G13: ='P&L'!G17 -> 681.08083 | H13: ='P&L'!H17 -> 806.71046 | I13: ='P&L'!I17 -> 419.54533 | J13: ='P&L'!J17 -> 243.9295 | K13: ='P&L'!K17 -> 784.68812 | L13: ='P&L'!L17 -> 1146.9279 | M13: ='P&L'!M17 -> 535.79477 | N13: ='P&L'!N17 -> 324.41686 | ... Z13: ='P&L'!Z17 -> 1007.8291
E14: EBITDA margin, % | F14: % | G14: =IFERROR(G13/G11,"-") -> 0.22522164 | H14: =IFERROR(H13/H11,"-") -> 0.25026702 | I14: =IFERROR(I13/I11,"-") -> 0.1885087 | J14: =IFERROR(J13/J11,"-") -> 0.12206063 | K14: =IFERROR(K13/K11,"-") -> 0.25638024 | L14: =IFERROR(L13/L11,"-") -> 0.29170206 | M14: =IFERROR(M13/M11,"-") -> 0.16317725 | N14: =IFERROR(N13/N11,"-") -> 0.12242317 | ... Z14: =IFERROR(Z13/Z11,"-") -> 0.20957267
E15: Операционный денежный поток | F15: млн $ | G15: =CFS!G12 -> 585.797 | H15: =CFS!H12 -> 801.017 | I15: =CFS!I12 -> 296.951 | J15: =CFS!J12 -> 249.93 | K15: =CFS!K12 -> 780.22 | L15: =CFS!L12 -> 980.206 | M15: =CFS!M12 -> 515.431 | N15: =CFS!N12 -> 461.082 | ... Z15: =CFS!Z12 -> 883.18181
E16: CapEx на поддержание | F16: млн $ | G16: =CFS!G15 -> -269.367 | H16: =CFS!H15 -> -84.168 | I16: =CFS!I15 -> -96.909 | J16: =CFS!J15 -> -99.881 | K16: =CFS!K15 -> -103.17 | L16: =CFS!L15 -> -244.476 | M16: =CFS!M15 -> -208.467 | N16: =CFS!N15 -> -128.786 | ... Z16: =CFS!Z15 -> -212.11736
E17: CapEx на расширение | F17: млн $ | G17: =CFS!G16 -> -309.469 | H17: =CFS!H16 -> -573.844 | I17: =CFS!I16 -> -328.112 | J17: =CFS!J16 -> 0 | K17: =CFS!K16 -> 0 | L17: =CFS!L16 -> 0 | M17: =CFS!M16 -> -115.393 | N17: =CFS!N16 -> -213.03 | ... Z17: =CFS!Z16 -> 0
E18: Инвестиционный денежный поток | F18: млн $ | G18: =CFS!G18 -> -526.429 | H18: =CFS!H18 -> -681.022 | I18: =CFS!I18 -> -426.255 | J18: =CFS!J18 -> -88.209 | K18: =CFS!K18 -> -105.517 | L18: =CFS!L18 -> -306.351 | M18: =CFS!M18 -> -250.692 | N18: =CFS!N18 -> -278.063 | ... Z18: =CFS!Z18 -> -212.11736
E19: Погашение долга | F19: млн $ | G19: =CFS!G21 -> -39.491 | H19: =CFS!H21 -> -41.504 | I19: =CFS!I21 -> -193.996 | J19: =CFS!J21 -> -48.417 | K19: =CFS!K21 -> -56.997 | L19: =CFS!L21 -> -213.622 | M19: =CFS!M21 -> -101.812 | N19: =CFS!N21 -> -106.834 | ... Z19: =CFS!Z21 -> -69.484
E20: PRES | F20: млн $ | G20: =CFS!G22 -> -55.446 | H20: =CFS!H22 -> -52.995 | I20: =CFS!I22 -> -82.275 | J20: =CFS!J22 -> -82.965 | K20: =CFS!K22 -> -86.041 | L20: =CFS!L22 -> -90.008 | M20: =CFS!M22 -> -115.283 | N20: =CFS!N22 -> -165.45 | ... Z20: =CFS!Z22 -> -50.92356
E21: Дивиденды | F21: млн $ | G21: =CFS!G23 -> -74.937 | H21: =CFS!H23 -> -89.913 | I21: =CFS!I23 -> -97.221 | J21: =CFS!J23 -> -98.797 | K21: =CFS!K23 -> -101.497 | L21: =CFS!L23 -> -105.676 | M21: =CFS!M23 -> -107.876 | N21: =CFS!N23 -> -36.004 | ... Z21: =CFS!Z23 -> -136.84317
E22: Финансовый денежный поток | F22: млн $ | G22: =CFS!G28 -> -54.017 | H22: =CFS!H28 -> 98.869 | I22: =CFS!I28 -> -567.362 | J22: =CFS!J28 -> -192.765 | K22: =CFS!K28 -> -523.114 | L22: =CFS!L28 -> -793.257 | M22: =CFS!M28 -> -104.053 | N22: =CFS!N28 -> 234.059 | ... Z22: =CFS!Z28 -> -257.25073
E23: Денежные средства на конец | F23: млн $ | G23: =CFS!G32 -> 732.736 | H23: =CFS!H32 -> 951.6 | I23: =CFS!I32 -> 254.934 | J23: =CFS!J32 -> 223.89 | K23: =CFS!K32 -> 375.479 | L23: =CFS!L32 -> 256.077 | M23: =CFS!M32 -> 416.763 | N23: =CFS!N32 -> 833.841 | ... Z23: =CFS!Z32 -> 2472.0674
E24: Долговые метрики
E25: Долг | F25: млн $ | G25: =SUM(G26:G27) -> 1168.306 | H25: =SUM(H26:H27) -> 1722.038 | I25: =SUM(I26:I27) -> 1535.89 | J25: =SUM(J26:J27) -> 1556.206 | K25: =SUM(K26:K27) -> 1502.271 | L25: =SUM(L26:L27) -> 1458.286 | M25: =SUM(M26:M27) -> 2487.358 | N25: =SUM(N26:N27) -> 3085.606 | ... Z25: =SUM(Z26:Z27) -> 489.579
E26: Долг | F26: млн $ | G26: =BS!G28+BS!G33 -> 1168.306 | H26: =BS!H28+BS!H33 -> 1722.038 | I26: =BS!I28+BS!I33 -> 1535.89 | J26: =BS!J28+BS!J33 -> 1556.206 | K26: =BS!K28+BS!K33 -> 1502.271 | L26: =BS!L28+BS!L33 -> 1458.286 | M26: =BS!M28+BS!M33 -> 1768.853 | N26: =BS!N28+BS!N33 -> 2363.372 | ... Z26: =BS!Z28+BS!Z33 -> 401.767
E27: Лизинг | F27: млн $ | G27: =BS!G29+BS!G34 -> 0 | H27: =BS!H29+BS!H34 -> 0 | I27: =BS!I29+BS!I34 -> 0 | J27: =BS!J29+BS!J34 -> 0 | K27: =BS!K29+BS!K34 -> 0 | L27: =BS!L29+BS!L34 -> 0 | M27: =BS!M29+BS!M34 -> 718.505 | N27: =BS!N29+BS!N34 -> 722.234 | ... Z27: =BS!Z29+BS!Z34 -> 87.812
E28: Чистый долг | F28: млн $ | G28: =G25-G23 -> 435.57 | H28: =H25-H23 -> 770.438 | I28: =I25-I23 -> 1280.956 | J28: =J25-J23 -> 1332.316 | K28: =K25-K23 -> 1126.792 | L28: =L25-L23 -> 1202.209 | M28: =M25-M23 -> 2070.595 | N28: =N25-N23 -> 2251.765 | ... Z28: =Z25-Z23 -> -1982.4884
E29: Долг/EBITDA | F29: x | G29: =IFERROR(G25/G13,"-") -> 1.7153705 | H29: =IFERROR(H25/H13,"-") -> 2.134642 | I29: =IFERROR(I25/I13,"-") -> 3.660844 | J29: =IFERROR(J25/J13,"-") -> 6.3797367 | K29: =IFERROR(K25/K13,"-") -> 1.9144817 | L29: =IFERROR(L25/L13,"-") -> 1.2714714 | M29: =IFERROR(M25/M13,"-") -> 4.6423708 | N29: =IFERROR(N25/N13,"-") -> 9.511238 | ... Z29: =IFERROR(Z25/Z13,"-") -> 0.48577581
E30: Чистый долг/EBITDA | F30: x | G30: =IFERROR(G28/G13,"-") -> 0.63952761 | H30: =IFERROR(H28/H13,"-") -> 0.95503658 | I30: =IFERROR(I28/I13,"-") -> 3.0532005 | J30: =IFERROR(J28/J13,"-") -> 5.4618895 | K30: =IFERROR(K28/K13,"-") -> 1.4359743 | L30: =IFERROR(L28/L13,"-") -> 1.0481993 | M30: =IFERROR(M28/M13,"-") -> 3.86453 | N30: =IFERROR(N28/N13,"-") -> 6.9409616 | ... Z30: =IFERROR(Z28/Z13,"-") -> -1.9670878
E31: ISCR | F31: x | G31: =IFERROR((G15+G16)/-G20,"-") -> 5.7069942 | H31: =IFERROR((H15+H16)/-H20,"-") -> 13.526729 | I31: =IFERROR((I15+I16)/-I20,"-") -> 2.4313826 | J31: =IFERROR((J15+J16)/-J20,"-") -> 1.8085819 | K31: =IFERROR((K15+K16)/-K20,"-") -> 7.868923 | L31: =IFERROR((L15+L16)/-L20,"-") -> 8.1740512 | M31: =IFERROR((M15+M16)/-M20,"-") -> 2.6626996 | N31: =IFERROR((N15+N16)/-N20,"-") -> 2.0084376 | ... Z31: =IFERROR((Z15+Z16)/-Z20,"-") -> 13.177878
E32: DSCR | F32: x | G32: =IFERROR((G15+G16)/-(G19+G20),"-") -> 3.3330524 | H32: =IFERROR((H15+H16)/-(H19+H20),"-") -> 7.585784 | I32: =IFERROR((I15+I16)/-(I19+I20),"-") -> 0.72407889 | J32: =IFERROR((J15+J16)/-(J19+J20),"-") -> 1.1420819 | K32: =IFERROR((K15+K16)/-(K19+K20),"-") -> 4.7333576 | L32: =IFERROR((L15+L16)/-(L19+L20),"-") -> 2.4231137 | M32: =IFERROR((M15+M16)/-(M19+M20),"-") -> 1.4139616 | N32: =IFERROR((N15+N16)/-(N19+N20),"-") -> 1.2204022 | ... Z32: =IFERROR((Z15+Z16)/-(Z19+Z20),"-") -> 5.573275
E33: Оценка бизнеса
E34: WACC | F34: % | G34: =DCF!$F$19 -> 0.11375701
E35: TGR | F35: % | G35: =DCF!$F$24 -> 0.02
E36: ΣDFCFF | F36: млн $ | G36: =SUM(DCF!R22:AA22) -> 3646.6789
E37: TV | F37: млн $ | G37: =DCF!AA25 -> 2729.4774
E38: EV | F38: млн $ | G38: =G36+G37 -> 6376.1563
E39: EV / EBITDA 2022 | F39: x | G39: =G38/P13 -> 6.7685605
E40: Equity | F40: млн $ | G40: =DCF!R31 -> 4161.2883
E41: Стоимость акции | F41: $ | G41: =DCF!R34 -> 58.055725
E42: Недооценка (переоценка) | F42: % | G42: =G41/41.66-1 -> 0.39356037
...

Sheet Scenario
B2: Index | E2: Measure | F2: Base | G2: =Calc!G2 -> 2013 | H2: =Calc!H2 -> 2014 | I2: =Calc!I2 -> 2015 | J2: =Calc!J2 -> 2016 | K2: =Calc!K2 -> 2017 | L2: =Calc!L2 -> 2018 | M2: =Calc!M2 -> 2019 | N2: =Calc!N2 -> 2020 | ... Z2: =Calc!Z2 -> 2032
F3: =PRINT!F2 -> 1 | G3: =Calc!G3 -> fact | H3: =Calc!H3 -> fact | I3: =Calc!I3 -> fact | J3: =Calc!J3 -> fact | K3: =Calc!K3 -> fact | L3: =Calc!L3 -> fact | M3: =Calc!M3 -> fact | N3: =Calc!N3 -> fact | ... Z3: =Calc!Z3 -> forecast
B5: Панель управления | F5: =DCF!R34 -> 58.055725 | J5: 1 | K5: =J5+1 -> 2 | L5: =K5+1 -> 3 | M5: =L5+1 -> 4 | N5: =M5+1 -> 5 | O5: =N5+1 -> 6 | P5: =O5+1 -> 7
J7: Sber | K7: Sber | L7: Sber | M7: Sber | N7: Sber | O7: Sber | P7: Sber
J8: Base (Price) | K8: Base (NG) | L8: Negative | M8: Optimistic | N8: Base (w/o G-3) | O8: Negative (w/o G-3) | P8: Optimistic (w/o G-3)
D9: Macro
D10: CPI US | E10: x | F10: =CHOOSE($F$3,J10,K10,L10,M10,N10,O10,P10,Q10,R10) -> 1 | G10: 1-Base, 2-Negative, 3-Optimistic | J10: 1 | K10: 1 | L10: 1 | M10: 1 | N10: 1 | O10: 1 | P10: 1
D11: Natural gas price Henry Hub | E11: x | F11: =CHOOSE($F$3,J11,K11,L11,M11,N11,O11,P11,Q11,R11) -> 1 | G11: 1-Base, 2-Negative, 3-Optimistic | J11: 1 | K11: 1 | L11: 1 | M11: 1 | N11: 1 | O11: 1 | P11: 1
D13: Revenue
D14: Production | E14: x | F14: =CHOOSE($F$3,J14,K14,L14,M14,N14,O14,P14,Q14,R14) -> 1 | G14: 1-2022, 2-Average, 3-Hard number | J14: 1 | K14: 1 | L14: 1 | M14: 1 | N14: 1 | O14: 1 | P14: 1
D15: Coeff. (if production - 3) | E15: % | F15: =CHOOSE($F$3,J15,K15,L15,M15,N15,O15,P15,Q15,R15) -> 0
D16: Methanex-produced methanol | E16: x | F16: =CHOOSE($F$3,J16,K16,L16,M16,N16,O16,P16,Q16,R16) -> 3 | G16: 1-2022, 2-Average, 3-Hard number | J16: 3 | K16: 3 | L16: 3 | M16: 3 | N16: 3 | O16: 3 | P16: 3
D17: Coeff. (if Methanex-produced methanol - 3) | E17: % | F17: =CHOOSE($F$3,J17,K17,L17,M17,N17,O17,P17,Q17,R17) -> 1 | J17: 1 | K17: 1 | L17: 1 | M17: 1 | N17: 1 | O17: 1 | P17: 1
D18: Purchased methanol | E18: x | F18: =CHOOSE($F$3,J18,K18,L18,M18,N18,O18,P18,Q18,R18) -> 2 | G18: 1-2022, 2-Average, 3-Hard number | J18: 2 | K18: 2 | L18: 2 | M18: 2 | N18: 2 | O18: 2 | P18: 2
D19: Coeff. (if purchased methanol - 3) | E19: % | F19: =CHOOSE($F$3,J19,K19,L19,M19,N19,O19,P19,Q19,R19) -> 0
D20: Commission sales | E20: x | F20: =CHOOSE($F$3,J20,K20,L20,M20,N20,O20,P20,Q20,R20) -> 2 | G20: 1-2022, 2-Average, 3-Hard number | J20: 2 | K20: 2 | L20: 2 | M20: 2 | N20: 2 | O20: 2 | P20: 2
D21: Coeff. (if commission sales - 3) | E21: % | F21: =CHOOSE($F$3,J21,K21,L21,M21,N21,O21,P21,Q21,R21) -> 0
D22: Price | E22: x | F22: =CHOOSE($F$3,J22,K22,L22,M22,N22,O22,P22,Q22,R22) -> 1 | G22: 1-Base, 2-Negative, 3-Optimistic | J22: 1 | K22: 1 | L22: 2 | M22: 3 | N22: 1 | O22: 2 | P22: 3
D24: OpEx
D25: Cost of raw materials | E25: x | F25: =CHOOSE($F$3,J25,K25,L25,M25,N25,O25,P25,Q25,R25) -> 1 | G25: 1-Price, 2-CPI, 3-Natural gas price Henry Hub | J25: 1 | K25: 3 | L25: 1 | M25: 1 | N25: 1 | O25: 1 | P25: 1
D26: Cost of purchased methanol | E26: x | F26: =CHOOSE($F$3,J26,K26,L26,M26,N26,O26,P26,Q26,R26) -> 1 | G26: 1-Price, 2-CPI | J26: 1 | K26: 1 | L26: 1 | M26: 1 | N26: 1 | O26: 1 | P26: 1
D27: Ocean freight and other logistics | E27: x | F27: =CHOOSE($F$3,J27,K27,L27,M27,N27,O27,P27,Q27,R27) -> 1 | G27: 1-Price, 2-CPI | J27: 1 | K27: 1 | L27: 1 | M27: 1 | N27: 1 | O27: 1 | P27: 1
D28: Employee expenses, including share-based compensation | E28: x | F28: =CHOOSE($F$3,J28,K28,L28,M28,N28,O28,P28,Q28,R28) -> 2 | G28: 1-Price, 2-CPI | J28: 2 | K28: 2 | L28: 2 | M28: 2 | N28: 2 | O28: 2 | P28: 2
D29: Other expenses | E29: x | F29: =CHOOSE($F$3,J29,K29,L29,M29,N29,O29,P29,Q29,R29) -> 2 | G29: 1-Price, 2-CPI | J29: 2 | K29: 2 | L29: 2 | M29: 2 | N29: 2 | O29: 2 | P29: 2
D31: CapEx
D32: Property, plant and equipment | E32: x | F32: =CHOOSE($F$3,J32,K32,L32,M32,N32,O32,P32,Q32,R32) -> 1 | G32: 1-CPI, 2-as % of Revenue | J32: 1 | K32: 1 | L32: 1 | M32: 1 | N32: 1 | O32: 1 | P32: 1
D33: USA (Geismar 3) | E33: x | F33: =CHOOSE($F$3,J33,K33,L33,M33,N33,O33,P33,Q33,R33) -> 1 | G33: 0-no, 1-yes | J33: 1 | K33: 1 | L33: 1 | M33: 1 | N33: 0 | O33: 0 | P33: 0
D34: Operation phase | E34: year | F34: =CHOOSE($F$3,J34,K34,L34,M34,N34,O34,P34,Q34,R34) -> 2024 | J34: 2024 | K34: 2024 | L34: 2024 | M34: 2024 | N34: 2024 | O34: 2024 | P34: 2024
D35: Production | E35: x | F35: =CHOOSE($F$3,J35,K35,L35,M35,N35,O35,P35,Q35,R35) -> 1800 | J35: 1800 | K35: 1800 | L35: 1800 | M35: 1800 | N35: 1800 | O35: 1800 | P35: 1800
D36: Coeff. | E36: % | F36: =CHOOSE($F$3,J36,K36,L36,M36,N36,O36,P36,Q36,R36) -> 0.9 | J36: 0.9 | K36: 0.9 | L36: 0.9 | M36: 0.9 | N36: 0.9 | O36: 0.9 | P36: 0.9
D37: CapEx remaining | E37: mn $ | F37: =CHOOSE($F$3,J37,K37,L37,M37,N37,O37,P37,Q37,R37) -> 440 | J37: =(415+465)/2 -> 440 | K37: =(415+465)/2 -> 440 | L37: =(415+465)/2 -> 440 | M37: =(415+465)/2 -> 440 | N37: =(415+465)/2 -> 440 | O37: =(415+465)/2 -> 440 | P37: =(415+465)/2 -> 440
D39: Valuation
D40: WACC | E40: % | F40: =CHOOSE($F$3,J40,K40,L40,M40,N40,O40,P40,Q40,R40) -> 0.11375701 | J40: 0.11375701 | K40: 0.11375701 | L40: 0.11375701 | M40: 0.11375701 | N40: 0.11375701 | O40: 0.11375701 | P40: 0.11375701
D41: TGR | E41: % | F41: =CHOOSE($F$3,J41,K41,L41,M41,N41,O41,P41,Q41,R41) -> 0.02 | J41: 0.02 | K41: 0.02 | L41: 0.02 | M41: 0.02 | N41: 0.02 | O41: 0.02 | P41: 0.02
B45: Sensitivity
J48: =F5 -> 58.055725 | K48: 2 | L48: 1 | M48: 3 | P48: 2 | Q48: 1 | R48: 3
J49: 0.14 | O49: 0.14
J50: 0.13 | O50: 0.13
J51: 0.12 | O51: 0.12
J52: 0.11375701 | O52: 0.11375701
...

Sheet Calc
Q1: =DATE(Q2,1,1) -> 44927 | R1: =DATE(R2,1,1) -> 45292 | S1: =DATE(S2,1,1) -> 45658 | T1: =DATE(T2,1,1) -> 46023 | U1: =DATE(U2,1,1) -> 46388 | V1: =DATE(V2,1,1) -> 46753 | W1: =DATE(W2,1,1) -> 47119 | X1: =DATE(X2,1,1) -> 47484 | ... Z1: =DATE(Z2,1,1) -> 48214
B2: Index | E2: Measure | F2: Base | G2: 2013 | H2: =G2+1 -> 2014 | I2: =H2+1 -> 2015 | J2: =I2+1 -> 2016 | K2: =J2+1 -> 2017 | L2: =K2+1 -> 2018 | M2: =L2+1 -> 2019 | N2: =M2+1 -> 2020 | O2: =N2+1 -> 2021 | ... Z2: =Y2+1 -> 2032
G3: fact | H3: fact | I3: fact | J3: fact | K3: fact | L3: fact | M3: fact | N3: fact | O3: fact | P3: fact | Q3: forecast | R3: forecast | S3: forecast | T3: forecast | U3: forecast | V3: forecast | W3: forecast | X3: forecast | Y3: forecast | Z3: forecast
B6: Macro
D8: CPI US | E8: % | F8: =Scenario!F10 -> 1 | G8: =CHOOSE($F8,G9,G10,G11) -> 0.016331 | H8: =CHOOSE($F8,H9,H10,H11) -> 0.0146123 | I8: =CHOOSE($F8,I9,I10,I11) -> 0.0125234 | J8: =CHOOSE($F8,J9,J10,J11) -> 0.0185337 | K8: =CHOOSE($F8,K9,K10,K11) -> 0.0163842 | L8: =CHOOSE($F8,L9,L10,L11) -> 0.019 | M8: =CHOOSE($F8,M9,M10,M11) -> 0.023 | N8: =CHOOSE($F8,N9,N10,N11) -> 0.014 | ... Z8: =CHOOSE($F8,Z9,Z10,Z11) -> 0.02
D9: Sber (base) | E9: % | G9: =Inputs!V4 -> 0.016331 | H9: =Inputs!W4 -> 0.0146123 | I9: =Inputs!X4 -> 0.0125234 | J9: =Inputs!Y4 -> 0.0185337 | K9: =Inputs!Z4 -> 0.0163842 | L9: =Inputs!AA4 -> 0.019 | M9: =Inputs!AB4 -> 0.023 | N9: =Inputs!AC4 -> 0.014 | ... Z9: =Inputs!AO4 -> 0.02
D10: Sber (negative) | E10: % | G10: ='Inputs sber (-)'!V4 -> 0.016331 | H10: ='Inputs sber (-)'!W4 -> 0.0146123 | I10: ='Inputs sber (-)'!X4 -> 0.0125234 | J10: ='Inputs sber (-)'!Y4 -> 0.0185337 | K10: ='Inputs sber (-)'!Z4 -> 0.0163842 | L10: ='Inputs sber (-)'!AA4 -> 0.019 | M10: ='Inputs sber (-)'!AB4 -> 0.023 | N10: ='Inputs sber (-)'!AC4 -> 0.014 | ... Z10: ='Inputs sber (-)'!AO4 -> 0.02
D11: Sber (optimistic) | E11: % | G11: ='Inputs sber (+)'!V4 -> 0.016331 | H11: ='Inputs sber (+)'!W4 -> 0.0146123 | I11: ='Inputs sber (+)'!X4 -> 0.0125234 | J11: ='Inputs sber (+)'!Y4 -> 0.0185337 | K11: ='Inputs sber (+)'!Z4 -> 0.0163842 | L11: ='Inputs sber (+)'!AA4 -> 0.019 | M11: ='Inputs sber (+)'!AB4 -> 0.023 | N11: ='Inputs sber (+)'!AC4 -> 0.014 | ... Z11: ='Inputs sber (+)'!AO4 -> 0.020591825
D13: Natural gas price Henry Hub | E13: $/mmBtu | F13: =Scenario!F11 -> 1 | G13: =CHOOSE($F13,G14,G15,G16) -> 0 | H13: =CHOOSE($F13,H14,H15,H16) -> 0 | I13: =CHOOSE($F13,I14,I15,I16) -> 2.6121 | J13: =CHOOSE($F13,J14,J15,J16) -> 2.4946 | K13: =CHOOSE($F13,K14,K15,K16) -> 2.9629 | L13: =CHOOSE($F13,L14,L15,L16) -> 3.1511 | M13: =CHOOSE($F13,M14,M15,M16) -> 2.5625 | N13: =CHOOSE($F13,N14,N15,N16) -> 2.0184177 | ... Z13: =CHOOSE($F13,Z14,Z15,Z16) -> 4.2317764
D14: Sber (base) | E14: $/mmBtu | G14: =Inputs!V249 -> 0 | H14: =Inputs!W249 -> 0 | I14: =Inputs!X249 -> 2.6121 | J14: =Inputs!Y249 -> 2.4946 | K14: =Inputs!Z249 -> 2.9629 | L14: =Inputs!AA249 -> 3.1511 | M14: =Inputs!AB249 -> 2.5625 | N14: =Inputs!AC249 -> 2.0184177 | ... Z14: =Inputs!AO249 -> 4.2317764
D15: Sber (negative) | E15: $/mmBtu | G15: ='Inputs sber (-)'!V249 -> 0 | H15: ='Inputs sber (-)'!W249 -> 0 | I15: ='Inputs sber (-)'!X249 -> 2.6121 | J15: ='Inputs sber (-)'!Y249 -> 2.4946 | K15: ='Inputs sber (-)'!Z249 -> 2.9629 | L15: ='Inputs sber (-)'!AA249 -> 3.1511 | M15: ='Inputs sber (-)'!AB249 -> 2.5625 | N15: ='Inputs sber (-)'!AC249 -> 2.0184177 | ... Z15: ='Inputs sber (-)'!AO249 -> 2.0740735
D16: Sber (optimistic) | E16: $/mmBtu | G16: ='Inputs sber (+)'!V249 -> 0 | H16: ='Inputs sber (+)'!W249 -> 0 | I16: ='Inputs sber (+)'!X249 -> 2.6121 | J16: ='Inputs sber (+)'!Y249 -> 2.4946 | K16: ='Inputs sber (+)'!Z249 -> 2.9629 | L16: ='Inputs sber (+)'!AA249 -> 3.1511 | M16: ='Inputs sber (+)'!AB249 -> 2.5625 | N16: ='Inputs sber (+)'!AC249 -> 2.0184177 | ... Z16: ='Inputs sber (+)'!AO249 -> 6.8698344
B20: Sales
C22: Production
D24: Operating Capacity | E24: ths t | G24: =SUM(G25:G31) -> 8340 | H24: =SUM(H25:H31) -> 8340 | I24: =SUM(I25:I31) -> 9380 | J24: =SUM(J25:J31) -> 9380 | K24: =SUM(K25:K31) -> 9380 | L24: =SUM(L25:L31) -> 9380 | M24: =SUM(M25:M31) -> 9150 | N24: =SUM(N25:N31) -> 9150 | ... Z24: =SUM(Z25:Z31) -> 11130
D25: USA (Geismar 1 & 2) | E25: ths t | G25: 1000 | H25: 1000 | I25: 2000 | J25: 2000 | K25: 2000 | L25: 2000 | M25: 2000 | N25: 2000 | O25: 2200 | P25: 2200 | Q25: =P25 -> 2200 | R25: =Q25 -> 2200 | S25: =R25 -> 2200 | T25: =S25 -> 2200 | U25: =T25 -> 2200 | V25: =U25 -> 2200 | W25: =V25 -> 2200 | X25: =W25 -> 2200 | ... Z25: =Y25 -> 2200
D26: USA (Geismar 3) | E26: ths t | F26: =Scenario!$F$33 -> 1 | G26: 0 | H26: 0 | I26: 0 | J26: 0 | K26: 0 | L26: 0 | M26: 0 | N26: 0 | O26: 0 | P26: 0 | Q26: =($F26*Scenario!$F$35)*(Scenario!$F34<=Q2) -> 0 | R26: =($F26*Scenario!$F$35)*(Scenario!$F34<=R2) -> 1800 | S26: =($F26*Scenario!$F$35)*(Scenario!$F34<=S2) -> 1800 | T26: =($F26*Scenario!$F$35)*(Scenario!$F34<=T2) -> 1800 | U26: =($F26*Scenario!$F$35)*(Scenario!$F34<=U2) -> 1800 | V26: =($F26*Scenario!$F$35)*(Scenario!$F34<=V2) -> 1800 | W26: =($F26*Scenario!$F$35)*(Scenario!$F34<=W2) -> 1800 | X26: =($F26*Scenario!$F$35)*(Scenario!$F34<=X2) -> 1800 | ... Z26: =($F26*Scenario!$F$35)*(Scenario!$F34<=Z2) -> 1800
D27: New Zealand | E27: ths t | G27: 2430 | H27: 2430 | I27: 2430 | J27: 2430 | K27: 2430 | L27: 2430 | M27: 2200 | N27: 2200 | O27: 2200 | P27: 2200 | Q27: =P27 -> 2200 | R27: =Q27 -> 2200 | S27: =R27 -> 2200 | T27: =S27 -> 2200 | U27: =T27 -> 2200 | V27: =U27 -> 2200 | W27: =V27 -> 2200 | X27: =W27 -> 2200 | ... Z27: =Y27 -> 2200
D28: Trinidad (Methanex interest) | E28: ths t | G28: 2000 | H28: 2000 | I28: 2000 | J28: 2000 | K28: 2000 | L28: 2000 | M28: 2000 | N28: 2000 | O28: 1960 | P28: 1960 | Q28: =P28 -> 1960 | R28: =Q28 -> 1960 | S28: =R28 -> 1960 | T28: =S28 -> 1960 | U28: =T28 -> 1960 | V28: =U28 -> 1960 | W28: =V28 -> 1960 | X28: =W28 -> 1960 | ... Z28: =Y28 -> 1960
D29: Chile | E29: ths t | G29: 1720 | H29: 1720 | I29: 1720 | J29: 1720 | K29: 1720 | L29: 1720 | M29: 1720 | N29: 1720 | O29: 1700 | P29: 1700 | Q29: =P29 -> 1700 | R29: =Q29 -> 1700 | S29: =R29 -> 1700 | T29: =S29 -> 1700 | U29: =T29 -> 1700 | V29: =U29 -> 1700 | W29: =V29 -> 1700 | X29: =W29 -> 1700 | ... Z29: =Y29 -> 1700
D30: Egypt (50% interest) | E30: ths t | G30: 630 | H30: 630 | I30: 630 | J30: 630 | K30: 630 | L30: 630 | M30: 630 | N30: 630 | O30: 630 | P30: 630 | Q30: =P30 -> 630 | R30: =Q30 -> 630 | S30: =R30 -> 630 | T30: =S30 -> 630 | U30: =T30 -> 630 | V30: =U30 -> 630 | W30: =V30 -> 630 | X30: =W30 -> 630 | ... Z30: =Y30 -> 630
D31: Canada (Medicine Hat) | E31: ths t | G31: 560 | H31: 560 | I31: 600 | J31: 600 | K31: 600 | L31: 600 | M31: 600 | N31: 600 | O31: 640 | P31: 640 | Q31: =P31 -> 640 | R31: =Q31 -> 640 | S31: =R31 -> 640 | T31: =S31 -> 640 | U31: =T31 -> 640 | V31: =U31 -> 640 | W31: =V31 -> 640 | X31: =W31 -> 640 | ... Z31: =Y31 -> 640
D33: Production | E33: % | F33: =Scenario!F14 -> 1 | G33: =IFERROR(G42/G24,) -> 0.52086331 | H33: =IFERROR(H42/H24,) -> 0.58189448 | I33: =IFERROR(I42/I24,) -> 0.55362473 | J33: =IFERROR(J42/J24,) -> 0.74808102 | K33: =IFERROR(K42/K24,) -> 0.76620469 | L33: =IFERROR(L42/L24,) -> 0.76876333 | M33: =IFERROR(M42/M24,) -> 0.82939891 | N33: =IFERROR(N42/N24,) -> 0.72284153 | ... Z33: =IFERROR(Z42/Z24,) -> 0.6952381
D34: USA (Geismar 1 & 2) | E34: % | G34: =IFERROR(G43/G25,) -> 0 | H34: =IFERROR(H43/H25,) -> 0 | I34: =IFERROR(I43/I25,) -> 0.4795 | J34: =IFERROR(J43/J25,) -> 1.0275 | K34: =IFERROR(K43/K25,) -> 0.9675 | L34: =IFERROR(L43/L25,) -> 1.039 | M34: =IFERROR(M43/M25,) -> 0.9645 | N34: =IFERROR(N43/N25,) -> 1.02 | ... P34: =IFERROR(P43/P25,) -> 0.92772727 | Q34: =CHOOSE($F$33,P34,AVERAGE($G34:$P34),Scenario!$F$15) -> 0.92772727 | R34: =CHOOSE($F$33,Q34,AVERAGE($G34:$P34),Scenario!$F$15) -> 0.92772727 | S34: =CHOOSE($F$33,R34,AVERAGE($G34:$P34),Scenario!$F$15) -> 0.92772727 | T34: =CHOOSE($F$33,S34,AVERAGE($G34:$P34),Scenario!$F$15) -> 0.92772727 | U34: =CHOOSE($F$33,T34,AVERAGE($G34:$P34),Scenario!$F$15) -> 0.92772727 | V34: =CHOOSE($F$33,U34,AVERAGE($G34:$P34),Scenario!$F$15) -> 0.92772727 | W34: =CHOOSE($F$33,V34,AVERAGE($G34:$P34),Scenario!$F$15) -> 0.92772727 | X34: =CHOOSE($F$33,W34,AVERAGE($G34:$P34),Scenario!$F$15) -> 0.92772727 | ... Z34: =CHOOSE($F$33,Y34,AVERAGE($G34:$P34),Scenario!$F$15) -> 0.92772727
D35: USA (Geismar 3) | E35: ths t | F35: =Scenario!$F$33 -> 1 | G35: =IFERROR(G44/G26,) -> 0 | H35: =IFERROR(H44/H26,) -> 0 | I35: =IFERROR(I44/I26,) -> 0 | J35: =IFERROR(J44/J26,) -> 0 | K35: =IFERROR(K44/K26,) -> 0 | L35: =IFERROR(L44/L26,) -> 0 | M35: =IFERROR(M44/M26,) -> 0 | N35: =IFERROR(N44/N26,) -> 0 | ... P35: =IFERROR(P44/P26,) -> 0 | Q35: =($F35*Scenario!$F$36)*(Scenario!$F34<=Q2) -> 0 | R35: =($F35*Scenario!$F$36)*(Scenario!$F34<=R2) -> 0.9 | S35: =($F35*Scenario!$F$36)*(Scenario!$F34<=S2) -> 0.9 | T35: =($F35*Scenario!$F$36)*(Scenario!$F34<=T2) -> 0.9 | U35: =($F35*Scenario!$F$36)*(Scenario!$F34<=U2) -> 0.9 | V35: =($F35*Scenario!$F$36)*(Scenario!$F34<=V2) -> 0.9 | W35: =($F35*Scenario!$F$36)*(Scenario!$F34<=W2) -> 0.9 | X35: =($F35*Scenario!$F$36)*(Scenario!$F34<=X2) -> 0.9 | ... Z35: =($F35*Scenario!$F$36)*(Scenario!$F34<=Z2) -> 0.9
D36: New Zealand | E36: % | G36: =IFERROR(G45/G27,) -> 0.58395062 | H36: =IFERROR(H45/H27,) -> 0.9037037 | I36: =IFERROR(I45/I27,) -> 0.76378601 | J36: =IFERROR(J45/J27,) -> 0.89753086 | K36: =IFERROR(K45/K27,) -> 0.79958848 | L36: =IFERROR(L45/L27,) -> 0.66090535 | M36: =IFERROR(M45/M27,) -> 0.84772727 | N36: =IFERROR(N45/N27,) -> 0.76 | ... P36: =IFERROR(P45/P27,) -> 0.55909091 | Q36: =CHOOSE($F$33,P36,AVERAGE($G36:$P36),Scenario!$F$15) -> 0.55909091 | R36: =CHOOSE($F$33,Q36,AVERAGE($G36:$P36),Scenario!$F$15) -> 0.55909091 | S36: =CHOOSE($F$33,R36,AVERAGE($G36:$P36),Scenario!$F$15) -> 0.55909091 | T36: =CHOOSE($F$33,S36,AVERAGE($G36:$P36),Scenario!$F$15) -> 0.55909091 | U36: =CHOOSE($F$33,T36,AVERAGE($G36:$P36),Scenario!$F$15) -> 0.55909091 | V36: =CHOOSE($F$33,U36,AVERAGE($G36:$P36),Scenario!$F$15) -> 0.55909091 | W36: =CHOOSE($F$33,V36,AVERAGE($G36:$P36),Scenario!$F$15) -> 0.55909091 | X36: =CHOOSE($F$33,W36,AVERAGE($G36:$P36),Scenario!$F$15) -> 0.55909091 | ... Z36: =CHOOSE($F$33,Y36,AVERAGE($G36:$P36),Scenario!$F$15) -> 0.55909091
D37: Trinidad (Methanex interest) | E37: % | G37: =IFERROR(G46/G28,) -> 0.811 | H37: =IFERROR(H46/H28,) -> 0.7855 | I37: =IFERROR(I46/I28,) -> 0.822 | J37: =IFERROR(J46/J28,) -> 0.8025 | K37: =IFERROR(K46/K28,) -> 0.884 | L37: =IFERROR(L46/L28,) -> 0.851 | M37: =IFERROR(M46/M28,) -> 0.8715 | N37: =IFERROR(N46/N28,) -> 0.499 | ... P37: =IFERROR(P46/P28,) -> 0.5005102 | Q37: =CHOOSE($F$33,P37,AVERAGE($G37:$P37),Scenario!$F$15) -> 0.5005102 | R37: =CHOOSE($F$33,Q37,AVERAGE($G37:$P37),Scenario!$F$15) -> 0.5005102 | S37: =CHOOSE($F$33,R37,AVERAGE($G37:$P37),Scenario!$F$15) -> 0.5005102 | T37: =CHOOSE($F$33,S37,AVERAGE($G37:$P37),Scenario!$F$15) -> 0.5005102 | U37: =CHOOSE($F$33,T37,AVERAGE($G37:$P37),Scenario!$F$15) -> 0.5005102 | V37: =CHOOSE($F$33,U37,AVERAGE($G37:$P37),Scenario!$F$15) -> 0.5005102 | W37: =CHOOSE($F$33,V37,AVERAGE($G37:$P37),Scenario!$F$15) -> 0.5005102 | X37: =CHOOSE($F$33,W37,AVERAGE($G37:$P37),Scenario!$F$15) -> 0.5005102 | ... Z37: =CHOOSE($F$33,Y37,AVERAGE($G37:$P37),Scenario!$F$15) -> 0.5005102
D38: Chile | E38: % | G38: =IFERROR(G47/G29,) -> 0.11860465 | H38: =IFERROR(H47/H29,) -> 0.095930233 | I38: =IFERROR(I47/I29,) -> 0.11860465 | J38: =IFERROR(J47/J29,) -> 0.22965116 | K38: =IFERROR(K47/K29,) -> 0.24069767 | L38: =IFERROR(L47/L29,) -> 0.35581395 | M38: =IFERROR(M47/M29,) -> 0.61046512 | N38: =IFERROR(N47/N29,) -> 0.48604651 | ... P38: =IFERROR(P47/P29,) -> 0.52235294 | Q38: =CHOOSE($F$33,P38,AVERAGE($G38:$P38),Scenario!$F$15) -> 0.52235294 | R38: =CHOOSE($F$33,Q38,AVERAGE($G38:$P38),Scenario!$F$15) -> 0.52235294 | S38: =CHOOSE($F$33,R38,AVERAGE($G38:$P38),Scenario!$F$15) -> 0.52235294 | T38: =CHOOSE($F$33,S38,AVERAGE($G38:$P38),Scenario!$F$15) -> 0.52235294 | U38: =CHOOSE($F$33,T38,AVERAGE($G38:$P38),Scenario!$F$15) -> 0.52235294 | V38: =CHOOSE($F$33,U38,AVERAGE($G38:$P38),Scenario!$F$15) -> 0.52235294 | W38: =CHOOSE($F$33,V38,AVERAGE($G38:$P38),Scenario!$F$15) -> 0.52235294 | X38: =CHOOSE($F$33,W38,AVERAGE($G38:$P38),Scenario!$F$15) -> 0.52235294 | ... Z38: =CHOOSE($F$33,Y38,AVERAGE($G38:$P38),Scenario!$F$15) -> 0.52235294
D39: Egypt (50% interest) | E39: % | G39: =IFERROR(G48/G30,) -> 0.98888889 | H39: =IFERROR(H48/H30,) -> 0.66031746 | I39: =IFERROR(I48/I30,) -> 0.11746032 | J39: =IFERROR(J48/J30,) -> 0.46507937 | K39: =IFERROR(K48/K30,) -> 0.84761905 | L39: =IFERROR(L48/L30,) -> 0.97301587 | M39: =IFERROR(M48/M30,) -> 0.62222222 | N39: =IFERROR(N48/N30,) -> 0.91746032 | ... P39: =IFERROR(P48/P30,) -> 0.61111111 | Q39: =CHOOSE($F$33,P39,AVERAGE($G39:$P39),Scenario!$F$15) -> 0.61111111 | R39: =CHOOSE($F$33,Q39,AVERAGE($G39:$P39),Scenario!$F$15) -> 0.61111111 | S39: =CHOOSE($F$33,R39,AVERAGE($G39:$P39),Scenario!$F$15) -> 0.61111111 | T39: =CHOOSE($F$33,S39,AVERAGE($G39:$P39),Scenario!$F$15) -> 0.61111111 | U39: =CHOOSE($F$33,T39,AVERAGE($G39:$P39),Scenario!$F$15) -> 0.61111111 | V39: =CHOOSE($F$33,U39,AVERAGE($G39:$P39),Scenario!$F$15) -> 0.61111111 | W39: =CHOOSE($F$33,V39,AVERAGE($G39:$P39),Scenario!$F$15) -> 0.61111111 | X39: =CHOOSE($F$33,W39,AVERAGE($G39:$P39),Scenario!$F$15) -> 0.61111111 | ... Z39: =CHOOSE($F$33,Y39,AVERAGE($G39:$P39),Scenario!$F$15) -> 0.61111111
D40: Canada (Medicine Hat) | E40: % | G40: =IFERROR(G49/G31,) -> 0.85 | H40: =IFERROR(H49/H31,) -> 0.90178571 | I40: =IFERROR(I49/I31,) -> 0.76 | J40: =IFERROR(J49/J31,) -> 0.81333333 | K40: =IFERROR(K49/K31,) -> 0.98833333 | L40: =IFERROR(L49/L31,) -> 1 | M40: =IFERROR(M49/M31,) -> 1.0166667 | N40: =IFERROR(N49/N31,) -> 0.81666667 | ... P40: =IFERROR(P49/P31,) -> 0.9265625 | Q40: =CHOOSE($F$33,P40,AVERAGE($G40:$P40),Scenario!$F$15) -> 0.9265625 | R40: =CHOOSE($F$33,Q40,AVERAGE($G40:$P40),Scenario!$F$15) -> 0.9265625 | S40: =CHOOSE($F$33,R40,AVERAGE($G40:$P40),Scenario!$F$15) -> 0.9265625 | T40: =CHOOSE($F$33,S40,AVERAGE($G40:$P40),Scenario!$F$15) -> 0.9265625 | U40: =CHOOSE($F$33,T40,AVERAGE($G40:$P40),Scenario!$F$15) -> 0.9265625 | V40: =CHOOSE($F$33,U40,AVERAGE($G40:$P40),Scenario!$F$15) -> 0.9265625 | W40: =CHOOSE($F$33,V40,AVERAGE($G40:$P40),Scenario!$F$15) -> 0.9265625 | X40: =CHOOSE($F$33,W40,AVERAGE($G40:$P40),Scenario!$F$15) -> 0.9265625 | ... Z40: =CHOOSE($F$33,Y40,AVERAGE($G40:$P40),Scenario!$F$15) -> 0.9265625
D42: Total production | E42: ths t | G42: =SUM(G43:G49) -> 4344 | H42: =SUM(H43:H49) -> 4853 | I42: =SUM(I43:I49) -> 5193 | J42: =SUM(J43:J49) -> 7017 | K42: =SUM(K43:K49) -> 7187 | L42: =SUM(L43:L49) -> 7211 | M42: =SUM(M43:M49) -> 7589 | N42: =SUM(N43:N49) -> 6614 | ... Z42: =SUM(Z43:Z49) -> 7738
D43: USA (Geismar 1 & 2) | E43: ths t | G43: 0 | H43: 0 | I43: 959 | J43: 2055 | K43: 1935 | L43: 2078 | M43: 1929 | N43: 2040 | O43: 1989 | P43: 2041 | Q43: =Q34*Q25 -> 2041 | R43: =R34*R25 -> 2041 | S43: =S34*S25 -> 2041 | T43: =T34*T25 -> 2041 | U43: =U34*U25 -> 2041 | V43: =V34*V25 -> 2041 | W43: =W34*W25 -> 2041 | X43: =X34*X25 -> 2041 | ... Z43: =Z34*Z25 -> 2041
D44: USA (Geismar 3) | E44: ths t | G44: 0 | H44: 0 | I44: 0 | J44: 0 | K44: 0 | L44: 0 | M44: 0 | N44: 0 | O44: 0 | P44: 0 | Q44: =Q35*Q26 -> 0 | R44: =R35*R26 -> 1620 | S44: =S35*S26 -> 1620 | T44: =T35*T26 -> 1620 | U44: =U35*U26 -> 1620 | V44: =V35*V26 -> 1620 | W44: =W35*W26 -> 1620 | X44: =X35*X26 -> 1620 | ... Z44: =Z35*Z26 -> 1620
D45: New Zealand | E45: ths t | G45: 1419 | H45: 2196 | I45: 1856 | J45: 2181 | K45: 1943 | L45: 1606 | M45: 1865 | N45: 1672 | O45: 1348 | P45: 1230 | Q45: =Q36*Q27 -> 1230 | R45: =R36*R27 -> 1230 | S45: =S36*S27 -> 1230 | T45: =T36*T27 -> 1230 | U45: =U36*U27 -> 1230 | V45: =V36*V27 -> 1230 | W45: =W36*W27 -> 1230 | X45: =X36*X27 -> 1230 | ... Z45: =Z36*Z27 -> 1230
D46: Trinidad (Methanex interest) | E46: ths t | G46: =651+971 -> 1622 | H46: =907+664 -> 1571 | I46: 1644 | J46: 1605 | K46: 1768 | L46: 1702 | M46: 1743 | N46: 998 | O46: 1161 | P46: 981 | Q46: =Q37*Q28 -> 981 | R46: =R37*R28 -> 981 | S46: =S37*S28 -> 981 | T46: =T37*T28 -> 981 | U46: =U37*U28 -> 981 | V46: =V37*V28 -> 981 | W46: =W37*W28 -> 981 | X46: =X37*X28 -> 981 | ... Z46: =Z37*Z28 -> 981
D47: Chile | E47: ths t | G47: 204 | H47: 165 | I47: 204 | J47: 395 | K47: 414 | L47: 612 | M47: 1050 | N47: 836 | O47: 807 | P47: 888 | Q47: =Q38*Q29 -> 888 | R47: =R38*R29 -> 888 | S47: =S38*S29 -> 888 | T47: =T38*T29 -> 888 | U47: =U38*U29 -> 888 | V47: =V38*V29 -> 888 | W47: =W38*W29 -> 888 | X47: =X38*X29 -> 888 | ... Z47: =Z38*Z29 -> 888
D48: Egypt (50% interest) | E48: ths t | G48: 623 | H48: 416 | I48: 74 | J48: 293 | K48: 534 | L48: 613 | M48: 392 | N48: 578 | O48: 581 | P48: 385 | Q48: =Q39*Q30 -> 385 | R48: =R39*R30 -> 385 | S48: =S39*S30 -> 385 | T48: =T39*T30 -> 385 | U48: =U39*U30 -> 385 | V48: =V39*V30 -> 385 | W48: =W39*W30 -> 385 | X48: =X39*X30 -> 385 | ... Z48: =Z39*Z30 -> 385
D49: Canada (Medicine Hat) | E49: ths t | G49: 476 | H49: 505 | I49: 456 | J49: 488 | K49: 593 | L49: 600 | M49: 610 | N49: 490 | O49: 628 | P49: 593 | Q49: =Q40*Q31 -> 593 | R49: =R40*R31 -> 593 | S49: =S40*S31 -> 593 | T49: =T40*T31 -> 593 | U49: =U40*U31 -> 593 | V49: =V40*V31 -> 593 | W49: =W40*W31 -> 593 | X49: =X40*X31 -> 593 | ... Z49: =Z40*Z31 -> 593
C52: Sales
D54: Methanex-produced methanol | E54: ths t | G54: 4304 | H54: 4878 | I54: 5050 | J54: 6828 | K54: 7229 | L54: 7002 | M54: 7611 | N54: 6704 | O54: 6207 | P54: 6141 | Q54: =Q55*Q$42 -> 6118 | R54: =R55*R$42 -> 7738 | S54: =S55*S$42 -> 7738 | T54: =T55*T$42 -> 7738 | U54: =U55*U$42 -> 7738 | V54: =V55*V$42 -> 7738 | W54: =W55*W$42 -> 7738 | X54: =X55*X$42 -> 7738 | ... Z54: =Z55*Z$42 -> 7738
...

Sheet P&L
B2: Index | E2: Measure | F2: Base | G2: =Calc!G2 -> 2013 | H2: =Calc!H2 -> 2014 | I2: =Calc!I2 -> 2015 | J2: =Calc!J2 -> 2016 | K2: =Calc!K2 -> 2017 | L2: =Calc!L2 -> 2018 | M2: =Calc!M2 -> 2019 | N2: =Calc!N2 -> 2020 | ... Z2: =Calc!Z2 -> 2032
G3: =Calc!G3 -> fact | H3: =Calc!H3 -> fact | I3: =Calc!I3 -> fact | J3: =Calc!J3 -> fact | K3: =Calc!K3 -> fact | L3: =Calc!L3 -> fact | M3: =Calc!M3 -> fact | N3: =Calc!N3 -> fact | ... Z3: =Calc!Z3 -> forecast
B6: P&L
D8: Revenue | E8: mn $ | G8: =Calc!G78 -> 3024.047 | H8: =Calc!H78 -> 3223.399 | I8: =Calc!I78 -> 2225.602 | J8: =Calc!J78 -> 1998.429 | K8: =Calc!K78 -> 3060.642 | L8: =Calc!L78 -> 3931.847 | M8: =Calc!M78 -> 3283.514 | N8: =Calc!N78 -> 2649.963 | ... Z8: =Calc!Z78 -> 4808.972
D10: Cost of raw materials and purchased methanol | E10: mn $ | G10: =Calc!G91 -> 1661.14 | H10: =Calc!H91 -> 1847.138 | I10: =Calc!I91 -> 1393.032 | J10: =Calc!J91 -> 1140.551 | K10: =Calc!K91 -> 1637.085 | L10: =Calc!L91 -> 2191.515 | M10: =Calc!M91 -> 2169.027 | N10: =Calc!N91 -> 1705.387 | ... Z10: =Calc!Z91 -> 3112.0545
D11: Ocean freight and other logistics | E11: mn $ | G11: =Calc!G97 -> 256.461 | H11: =Calc!H97 -> 287.35 | I11: =Calc!I97 -> 253.394 | J11: =Calc!J97 -> 351.609 | K11: =Calc!K97 -> 374.717 | L11: =Calc!L97 -> 399.293 | M11: =Calc!M97 -> 334.65 | N11: =Calc!N97 -> 328.635 | ... Z11: =Calc!Z97 -> 363.52168
D12: Employee expenses, including share-based compensation | E12: mn $ | G12: =Calc!G102 -> 274.463 | H12: =Calc!H102 -> 124.111 | I12: =Calc!I102 -> 113.627 | J12: =Calc!J102 -> 204.762 | K12: =Calc!K102 -> 243.707 | L12: =Calc!L102 -> 182.519 | M12: =Calc!M102 -> 184.171 | N12: =Calc!N102 -> 246.779 | ... Z12: =Calc!Z102 -> 270.54469
D13: Other expenses | E13: mn $ | G13: =Calc!G103 -> 173.456 | H13: =Calc!H103 -> 167.222 | I13: =Calc!I103 -> 97.846 | J13: =Calc!J103 -> 77.507 | K13: =Calc!K103 -> 96.44 | L13: =Calc!L103 -> 83.593 | M13: =Calc!M103 -> 112.089 | N13: =Calc!N103 -> 74.322 | ... Z13: =Calc!Z103 -> 137.45758
D15: Earnings of associate | E15: mn $ | G15: =Calc!G217 -> 22.553833 | H15: =Calc!H217 -> 9.132463 | I15: =Calc!I217 -> 51.842329 | J15: =Calc!J217 -> 19.929504 | K15: =Calc!K217 -> 75.995116 | L15: =Calc!L217 -> 72.000886 | M15: =Calc!M217 -> 52.217774 | N15: =Calc!N217 -> 29.576863 | ... Z15: =Calc!Z217 -> 82.435551
D17: EBITDA | E17: mn $ | G17: =G8-SUM(G10:G13)+G15 -> 681.08083 | H17: =H8-SUM(H10:H13)+H15 -> 806.71046 | I17: =I8-SUM(I10:I13)+I15 -> 419.54533 | J17: =J8-SUM(J10:J13)+J15 -> 243.9295 | K17: =K8-SUM(K10:K13)+K15 -> 784.68812 | L17: =L8-SUM(L10:L13)+L15 -> 1146.9279 | M17: =M8-SUM(M10:M13)+M15 -> 535.79477 | N17: =N8-SUM(N10:N13)+N15 -> 324.41686 | ... Z17: =Z8-SUM(Z10:Z13)+Z15 -> 1007.8291
D18: EBITDA margin | E18: % | G18: =IFERROR(G17/G$8,"-") -> 0.22522164 | H18: =IFERROR(H17/H$8,"-") -> 0.25026702 | I18: =IFERROR(I17/I$8,"-") -> 0.1885087 | J18: =IFERROR(J17/J$8,"-") -> 0.12206063 | K18: =IFERROR(K17/K$8,"-") -> 0.25638024 | L18: =IFERROR(L17/L$8,"-") -> 0.29170206 | M18: =IFERROR(M17/M$8,"-") -> 0.16317725 | N18: =IFERROR(N17/N$8,"-") -> 0.12242317 | ... Z18: =IFERROR(Z17/Z$8,"-") -> 0.20957267
D20: D&A | E20: mn $ | G20: =Calc!G122 -> 0 | H20: =Calc!H122 -> 142.738 | I20: =Calc!I122 -> 194.849 | J20: =Calc!J122 -> 228.054 | K20: =Calc!K122 -> 232.225 | L20: =Calc!L122 -> 245.303 | M20: =Calc!M122 -> 344.127 | N20: =Calc!N122 -> 357.129 | ... Z20: =Calc!Z122 -> 284.61719
D22: EBIT | E22: mn $ | G22: =G17-G20 -> 681.08083 | H22: =H17-H20 -> 663.97246 | I22: =I17-I20 -> 224.69633 | J22: =J17-J20 -> 15.875504 | K22: =K17-K20 -> 552.46312 | L22: =L17-L20 -> 901.62489 | M22: =M17-M20 -> 191.66777 | N22: =N17-N20 -> -32.712137 | ... Z22: =Z17-Z20 -> 723.21193
D23: EBIT margin | E23: % | G23: =IFERROR(G22/G$8,"-") -> 0.22522164 | H23: =IFERROR(H22/H$8,"-") -> 0.20598519 | I23: =IFERROR(I22/I$8,"-") -> 0.1009598 | J23: =IFERROR(J22/J$8,"-") -> 0.007943992 | K23: =IFERROR(K22/K$8,"-") -> 0.18050563 | L23: =IFERROR(L22/L$8,"-") -> 0.22931332 | M23: =IFERROR(M22/M$8,"-") -> 0.05837276 | N23: =IFERROR(N22/N$8,"-") -> -0.012344375 | ... Z23: =IFERROR(Z22/Z$8,"-") -> 0.15038805
D25: Other income (expenses) | E25: mn $ | G25: =-33.867-24.798 -> -58.665 | H25: =42-7.285 -> 34.715 | I25: =65-6.487 -> 58.513 | J25: 32.5 | K25: 0 | L25: 0 | M25: 50 | N25: 9.839 | O25: 0 | P25: 117.946
D26: Finance costs | E26: mn $ | G26: 56.407 | H26: 37.042 | I26: 69.859 | J26: 90.06 | K26: 94.955 | L26: 94.416 | M26: 124.426 | N26: 164.837 | O26: 144.406 | P26: 130.752 | Q26: =-CFS!Q22 -> 159.47333 | R26: =-CFS!R22 -> 153.21145 | S26: =-CFS!S22 -> 136.3408 | T26: =-CFS!T22 -> 131.3938 | U26: =-CFS!U22 -> 118.83692 | V26: =-CFS!V22 -> 90.88429 | W26: =-CFS!W22 -> 89.18418 | X26: =-CFS!X22 -> 54.381933 | ... Z26: =-CFS!Z22 -> 50.92356
D27: Finance income | E27: mn $ | G27: 4.446 | H27: 0 | I27: 0 | J27: 4.18 | K27: 13.377 | L27: 4.266 | M27: 3.598 | N27: 0.278 | O27: 1.036 | P27: 25.348
D29: Income before income taxes | E29: mn $ | G29: =G22+G25-G26+G27 -> 570.45483 | H29: =H22+H25-H26+H27 -> 661.64546 | I29: =I22+I25-I26+I27 -> 213.35033 | J29: =J22+J25-J26+J27 -> -37.504496 | K29: =K22+K25-K26+K27 -> 470.88512 | L29: =L22+L25-L26+L27 -> 811.47489 | M29: =M22+M25-M26+M27 -> 120.83977 | N29: =N22+N25-N26+N27 -> -187.43214 | ... Z29: =Z22+Z25-Z26+Z27 -> 672.28837
D31: Убыток прошлых лет | E31: mn $ | Q31: =SUM(P31:P33) -> 0 | R31: =SUM(Q31:Q33) -> 0 | S31: =SUM(R31:R33) -> 0 | T31: =SUM(S31:S33) -> 0 | U31: =SUM(T31:T33) -> 0 | V31: =SUM(U31:U33) -> 0 | W31: =SUM(V31:V33) -> 0 | X31: =SUM(W31:W33) -> 0 | ... Z31: =SUM(Y31:Y33) -> 0
D32: Убыток периода | E32: mn $ | Q32: =-IF(Q29<0,Q29,) -> 0 | R32: =-IF(R29<0,R29,) -> 0 | S32: =-IF(S29<0,S29,) -> 0 | T32: =-IF(T29<0,T29,) -> 0 | U32: =-IF(U29<0,U29,) -> 0 | V32: =-IF(V29<0,V29,) -> 0 | W32: =-IF(W29<0,W29,) -> 0 | X32: =-IF(X29<0,X29,) -> 0 | ... Z32: =-IF(Z29<0,Z29,) -> 0
D33: Зачет убытка | E33: mn $ | Q33: =-IF(AND(Q29>0,Q31>0,Q31>Q29),Q29,Q31) -> 0 | R33: =-IF(AND(R29>0,R31>0,R31>R29),R29,R31) -> 0 | S33: =-IF(AND(S29>0,S31>0,S31>S29),S29,S31) -> 0 | T33: =-IF(AND(T29>0,T31>0,T31>T29),T29,T31) -> 0 | U33: =-IF(AND(U29>0,U31>0,U31>U29),U29,U31) -> 0 | V33: =-IF(AND(V29>0,V31>0,V31>V29),V29,V31) -> 0 | W33: =-IF(AND(W29>0,W31>0,W31>W29),W29,W31) -> 0 | X33: =-IF(AND(X29>0,X31>0,X31>X29),X29,X31) -> 0 | ... Z33: =-IF(AND(Z29>0,Z31>0,Z31>Z29),Z29,Z31) -> 0
D34: Налогооблагаемая прибыль | E34: mn $ | Q34: =MAX(Q29+Q33,0) -> 81.963228 | R34: =MAX(R29+R33,0) -> 417.97706 | S34: =MAX(S29+S33,0) -> 586.35825 | T34: =MAX(T29+T33,0) -> 549.48934 | U34: =MAX(U29+U33,0) -> 566.90558 | V34: =MAX(V29+V33,0) -> 605.15753 | W34: =MAX(W29+W33,0) -> 615.64542 | X34: =MAX(X29+X33,0) -> 657.86825 | ... Z34: =MAX(Z29+Z33,0) -> 672.28837
D36: Income tax rate | E36: % | G36: =G37/G29 -> 0.12291946 | H36: =H37/H29 -> 0.23477377 | I36: =I37/I29 -> 0.051544331 | J36: =J37/J29 -> 0.24741034 | K36: =K37/K29 -> 0.20342117 | L36: =L37/L29 -> 0.18915065 | M36: =M37/M29 -> 0.037024233 | N36: =N37/N29 -> 0.33134659 | ... P36: =P37/P29 -> 0.20589113 | Q36: =AVERAGE($O36:$P36) -> 0.18580673 | R36: =AVERAGE($O36:$P36) -> 0.18580673 | S36: =AVERAGE($O36:$P36) -> 0.18580673 | T36: =AVERAGE($O36:$P36) -> 0.18580673 | U36: =AVERAGE($O36:$P36) -> 0.18580673 | V36: =AVERAGE($O36:$P36) -> 0.18580673 | W36: =AVERAGE($O36:$P36) -> 0.18580673 | X36: =AVERAGE($O36:$P36) -> 0.18580673 | ... Z36: =AVERAGE($O36:$P36) -> 0.18580673
D37: Income tax (expense) recovery | E37: mn $ | G37: 70.12 | H37: 155.337 | I37: 10.997 | J37: -9.279 | K37: 95.788 | L37: 153.491 | M37: 4.474 | N37: -62.105 | O37: 110.427 | P37: 119.859 | Q37: =Q34*Q36 -> 15.229319 | R37: =R34*R36 -> 77.662949 | S37: =S34*S36 -> 108.94931 | T37: =T34*T36 -> 102.09881 | U37: =U34*U36 -> 105.33487 | V37: =V34*V36 -> 112.44234 | W37: =W34*W36 -> 114.39106 | X37: =X34*X36 -> 122.23634 | ... Z37: =Z34*Z36 -> 124.9157
D39: Net profit | E39: mn $ | G39: =G29-G37 -> 500.33483 | H39: =H29-H37 -> 506.30846 | I39: =I29-I37 -> 202.35333 | J39: =J29-J37 -> -28.225496 | K39: =K29-K37 -> 375.09712 | L39: =L29-L37 -> 657.98389 | M39: =M29-M37 -> 116.36577 | N39: =N29-N37 -> -125.32714 | ... Z39: =Z29-Z37 -> 547.37267
D40: Рентабельность по чистой прибыли | E40: % | G40: =IFERROR(G39/G$8,"-") -> 0.16545207 | H40: =IFERROR(H39/H$8,"-") -> 0.15707285 | I40: =IFERROR(I39/I$8,"-") -> 0.090920717 | J40: =IFERROR(J39/J$8,"-") -> -0.014123842 | K40: =IFERROR(K39/K$8,"-") -> 0.12255504 | L40: =IFERROR(L39/L$8,"-") -> 0.16734728 | M40: =IFERROR(M39/M$8,"-") -> 0.035439402 | N40: =IFERROR(N39/N$8,"-") -> -0.04729392 | ... Z40: =IFERROR(Z39/Z$8,"-") -> 0.11382322
D43: Net profit (GAAP) | E43: mn $ | G43: 377 | H43: 506.308 | I43: 202.353 | J43: -28.225 | K43: 375.097 | L43: 657.984 | M43: 116.366 | N43: -125.327 | O43: 555.911 | P43: 462.288
D44: Check | E44: mn $ | G44: =G39-G43 -> 123.33483 | H44: =H39-H43 -> 0.000463 | I44: =I39-I43 -> 0.000329 | J44: =J39-J43 -> -0.000496 | K44: =K39-K43 -> 0.000116 | L44: =L39-L43 -> -0.000114 | M44: =M39-M43 -> -0.000226 | N44: =N39-N43 -> -0.000137 | ... P44: =P39-P43 -> 0.000461
B48: . | C48: . | D48: . | E48: . | F48: . | G48: . | V48: . | W48: . | X48: . | Y48: . | Z48: .

Sheet CFS
B2: Index | E2: Measure | F2: Base | G2: =Calc!G2 -> 2013 | H2: =Calc!H2 -> 2014 | I2: =Calc!I2 -> 2015 | J2: =Calc!J2 -> 2016 | K2: =Calc!K2 -> 2017 | L2: =Calc!L2 -> 2018 | M2: =Calc!M2 -> 2019 | N2: =Calc!N2 -> 2020 | ... Z2: =Calc!Z2 -> 2032
G3: =Calc!G3 -> fact | H3: =Calc!H3 -> fact | I3: =Calc!I3 -> fact | J3: =Calc!J3 -> fact | K3: =Calc!K3 -> fact | L3: =Calc!L3 -> fact | M3: =Calc!M3 -> fact | N3: =Calc!N3 -> fact | ... Z3: =Calc!Z3 -> forecast
B6: CFS
D8: EBITDA | E8: mn $ | G8: ='P&L'!G17 -> 681.08083 | H8: ='P&L'!H17 -> 806.71046 | I8: ='P&L'!I17 -> 419.54533 | J8: ='P&L'!J17 -> 243.9295 | K8: ='P&L'!K17 -> 784.68812 | L8: ='P&L'!L17 -> 1146.9279 | M8: ='P&L'!M17 -> 535.79477 | N8: ='P&L'!N17 -> 324.41686 | ... Z8: ='P&L'!Z17 -> 1007.8291
D9: Profit tax | E9: mn $ | G9: =-'P&L'!G37 -> -70.12 | H9: =-'P&L'!H37 -> -155.337 | I9: =-'P&L'!I37 -> -10.997 | J9: =-'P&L'!J37 -> 9.279 | K9: =-'P&L'!K37 -> -95.788 | L9: =-'P&L'!L37 -> -153.491 | M9: =-'P&L'!M37 -> -4.474 | N9: =-'P&L'!N37 -> 62.105 | ... Z9: =-'P&L'!Z37 -> -124.9157
D10: ΔNWC | E10: mn $ | G10: =-(Calc!G202-Calc!F202) -> -271.45 | H10: =-(Calc!H202-Calc!G202) -> 104.029 | I10: =-(Calc!I202-Calc!H202) -> -101.084 | J10: =-(Calc!J202-Calc!I202) -> -10.056 | K10: =-(Calc!K202-Calc!J202) -> 37.73 | L10: =-(Calc!L202-Calc!K202) -> -76.823 | M10: =-(Calc!M202-Calc!L202) -> 3.83 | N10: =-(Calc!N202-Calc!M202) -> 160.335 | ... Z10: =-(Calc!Z202-Calc!Y202) -> 0.26839222
D12: OCF | E12: mn $ | G12: 585.797 | H12: 801.017 | I12: 296.951 | J12: 249.93 | K12: 780.22 | L12: 980.206 | M12: 515.431 | N12: 461.082 | O12: 994.369 | P12: 987.349 | Q12: =Q8+SUM(Q9:Q10) -> 605.80242 | R12: =R8+SUM(R9:R10) -> 778.40913 | S12: =S8+SUM(S9:S10) -> 939.82855 | T12: =T8+SUM(T9:T10) -> 939.28993 | U12: =U8+SUM(U9:U10) -> 914.8233 | V12: =V8+SUM(V9:V10) -> 904.09588 | W12: =W8+SUM(W9:W10) -> 900.23727 | X12: =X8+SUM(X9:X10) -> 890.37811 | ... Z12: =Z8+SUM(Z9:Z10) -> 883.18181
D15: Property, plant and equipment | E15: mn $ | G15: =-Calc!G109 -> -269.367 | H15: =-Calc!H109 -> -84.168 | I15: =-Calc!I109 -> -96.909 | J15: =-Calc!J109 -> -99.881 | K15: =-Calc!K109 -> -103.17 | L15: =-Calc!L109 -> -244.476 | M15: =-Calc!M109 -> -208.467 | N15: =-Calc!N109 -> -128.786 | ... P15: =-Calc!P109 -> -145.701 | Q15: =-Calc!Q109-Calc!Q114 -> -150.34062 | R15: =-Calc!R109-Calc!R114 -> -180.83022 | S15: =-Calc!S109-Calc!S114 -> -184.55384 | T15: =-Calc!T109-Calc!T114 -> -188.35414 | U15: =-Calc!U109-Calc!U114 -> -192.12123 | V15: =-Calc!V109-Calc!V114 -> -195.96365 | W15: =-Calc!W109-Calc!W114 -> -199.88292 | X15: =-Calc!X109-Calc!X114 -> -203.88058 | ... Z15: =-Calc!Z109-Calc!Z114 -> -212.11736
D16: Geismar plant under construction | E16: mn $ | G16: =-Calc!G112 -> -309.469 | H16: =-Calc!H112 -> -573.844 | I16: =-Calc!I112 -> -328.112 | J16: =-Calc!J112 -> 0 | K16: =-Calc!K112 -> 0 | L16: =-Calc!L112 -> 0 | M16: =-Calc!M112 -> -115.393 | N16: =-Calc!N112 -> -213.03 | ... Z16: =-Calc!Z112 -> 0
D18: ICF | E18: mn $ | G18: -526.429 | H18: -681.022 | I18: -426.255 | J18: -88.209 | K18: -105.517 | L18: -306.351 | M18: -250.692 | N18: -278.063 | O18: -253.048 | P18: -553.137 | Q18: =SUM(Q15:Q16) -> -590.34062 | R18: =SUM(R15:R16) -> -180.83022 | S18: =SUM(S15:S16) -> -184.55384 | T18: =SUM(T15:T16) -> -188.35414 | U18: =SUM(U15:U16) -> -192.12123 | V18: =SUM(V15:V16) -> -195.96365 | W18: =SUM(W15:W16) -> -199.88292 | X18: =SUM(X15:X16) -> -203.88058 | ... Z18: =SUM(Z15:Z16) -> -212.11736
